Workbook

Sheet Ecommerce_Data
A1: Order_ID | B1: Order_Date | C1: Customer_ID | D1: Customer_Name | E1: City | F1: State | G1: Product | H1: Category | I1: Sub_Category | J1: cost | K1: MRP | L1: Quantity | M1: Discount | N1: Revenue | O1: Total_cost | P1: Profit | Q1: Payment_Method | R1: Order_status | S1: Delivery_date | T1: Shipping_Delay | U1: Rating | V1: Returned | W1: Return_count
A2: ORD00452 | B2: 44927 | C2: CUST0188 | D2: Vikram | E2: Bangalore | F2: Karnataka | G2: Mixer | H2: Home | I2: Kitchen | J2: 4109 | K2: 4597.4149 | L2: 5 | M2: 0 | N2: =K2*L2*(1-M2/100) -> 22987.075 | O2: =J2*L2 -> 20545 | P2: =N2-O2 -> 2442.0746 | Q2: COD | R2: Delivered | S2: 44935 | T2: 5 | U2: 4 | V2: No | W2: =IF(AND(NOT(R2="Cancelled"),V2="Yes"),1,0) -> 0
A3: ORD00033 | B3: 44928 | C3: CUST0025 | D3: Priya | E3: Ahmedabad | F3: Gujarat | G3: Mixer | H3: Home | I3: Kitchen | J3: 5503 | K3: 8127.667 | L3: 2 | M3: 0 | N3: =K3*L3*(1-M3/100) -> 16255.334 | O3: =J3*L3 -> 11006 | P3: =N3-O3 -> 5249.3339 | Q3: Debit Card | R3: Delivered | S3: 44941 | T3: 6 | U3: 2 | V3: No | W3: =IF(AND(NOT(R3="Cancelled"),V3="Yes"),1,0) -> 0
A4: ORD00228 | B4: 44928 | C4: CUST0058 | D4: Kiran | E4: Ahmedabad | F4: Gujarat | G4: T-Shirt | H4: Clothing | I4: Men | J4: 563 | K4: 585.86996 | L4: 1 | M4: 15 | N4: =K4*L4*(1-M4/100) -> 497.98947 | O4: =J4*L4 -> 563 | P4: =N4-O4 -> -65.01053 | Q4: Credit Card | R4: Delivered | S4: 44934 | T4: 3 | U4: 3 | V4: No | W4: =IF(AND(NOT(R4="Cancelled"),V4="Yes"),1,0) -> 0
A5: ORD00372 | B5: 44928 | C5: CUST0178 | D5: Priya | E5: Chennai | F5: Tamil Nadu | G5: T-Shirt | H5: Clothing | I5: Men | J5: 505 | K5: 566.79693 | L5: 3 | M5: 5 | N5: =K5*L5*(1-M5/100) -> 1615.3712 | O5: =J5*L5 -> 1515 | P5: =N5-O5 -> 100.37125 | Q5: Debit Card | R5: Delivered | S5: 44935 | T5: 2 | U5: 5 | V5: No | W5: =IF(AND(NOT(R5="Cancelled"),V5="Yes"),1,0) -> 0
A6: ORD01079 | B6: 44928 | C6: CUST0127 | D6: Nikhil | E6: Pune | F6: Maharashtra | G6: T-Shirt | H6: Clothing | I6: Men | J6: 566 | K6: 743.87909 | L6: 3 | M6: 10 | N6: =K6*L6*(1-M6/100) -> 2008.4735 | O6: =J6*L6 -> 1698 | P6: =N6-O6 -> 310.47354 | Q6: COD | R6: Cancelled | T6: 8 | U6: 4 | W6: =IF(AND(NOT(R6="Cancelled"),V6="Yes"),1,0) -> 0
A7: ORD00980 | B7: 44929 | C7: CUST0263 | D7: Neha | E7: Hyderabad | F7: Telangana | G7: Mixer | H7: Home | I7: Kitchen | J7: 6377 | K7: 7324.9864 | L7: 1 | M7: 20 | N7: =K7*L7*(1-M7/100) -> 5859.9891 | O7: =J7*L7 -> 6377 | P7: =N7-O7 -> -517.01088 | Q7: Debit Card | R7: Delivered | S7: 44937 | T7: 5 | U7: 2 | V7: No | W7: =IF(AND(NOT(R7="Cancelled"),V7="Yes"),1,0) -> 0
A8: ORD01015 | B8: 44929 | C8: CUST0174 | D8: Sneha | E8: Ahmedabad | F8: Gujarat | G8: Mixer | H8: Home | I8: Kitchen | J8: 5122 | K8: 7138.7011 | L8: 3 | M8: 10 | N8: =K8*L8*(1-M8/100) -> 19274.493 | O8: =J8*L8 -> 15366 | P8: =N8-O8 -> 3908.4931 | Q8: COD | R8: Delivered | S8: 44937 | T8: 5 | U8: 4 | V8: No | W8: =IF(AND(NOT(R8="Cancelled"),V8="Yes"),1,0) -> 0
A9: ORD00191 | B9: 44930 | C9: CUST0015 | D9: Kiran | E9: Ahmedabad | F9: Gujarat | G9: T-Shirt | H9: Clothing | I9: Men | J9: 389 | K9: 486.42563 | L9: 3 | M9: 0 | N9: =K9*L9*(1-M9/100) -> 1459.2769 | O9: =J9*L9 -> 1167 | P9: =N9-O9 -> 292.27688 | Q9: COD | R9: Cancelled | T9: 7 | U9: 2 | W9: =IF(AND(NOT(R9="Cancelled"),V9="Yes"),1,0) -> 0
A10: ORD00344 | B10: 44930 | C10: CUST0126 | D10: Priya | E10: Mumbai | F10: Maharashtra | G10: Dress | H10: Clothing | I10: Women | J10: 804 | K10: 823.5958 | L10: 4 | M10: 15 | N10: =K10*L10*(1-M10/100) -> 2800.2257 | O10: =J10*L10 -> 3216 | P10: =N10-O10 -> -415.77428 | Q10: COD | R10: Delivered | S10: 44942 | T10: 5 | U10: 2 | V10: No | W10: =IF(AND(NOT(R10="Cancelled"),V10="Yes"),1,0) -> 0
A11: ORD00408 | B11: 44930 | C11: CUST0116 | D11: Manoj | E11: Hyderabad | F11: Telangana | G11: Headphones | H11: Electronics | I11: Accessories | J11: 1025 | K11: 1706.6954 | L11: 5 | M11: 5 | N11: =K11*L11*(1-M11/100) -> 8106.8031 | O11: =J11*L11 -> 5125 | P11: =N11-O11 -> 2981.8031 | Q11: Debit Card | R11: Delivered | S11: 44943 | T11: 6 | U11: 2 | V11: No | W11: =IF(AND(NOT(R11="Cancelled"),V11="Yes"),1,0) -> 0
A12: ORD00423 | B12: 44930 | C12: CUST0139 | D12: Priya | E12: Delhi | F12: Delhi | G12: Shoes | H12: Clothing | I12: Footwear | J12: 722 | K12: 1293.6534 | L12: 4 | M12: 20 | N12: =K12*L12*(1-M12/100) -> 4139.6908 | O12: =J12*L12 -> 2888 | P12: =N12-O12 -> 1251.6908 | Q12: UPI | R12: Cancelled | T12: 9 | U12: 1 | W12: =IF(AND(NOT(R12="Cancelled"),V12="Yes"),1,0) -> 0
A13: ORD01167 | B13: 44930 | C13: CUST0176 | D13: Rahul | E13: Ahmedabad | F13: Gujarat | G13: Sofa | H13: Home | I13: Furniture | J13: 35408 | K13: 49239.02 | L13: 2 | M13: 0 | N13: =K13*L13*(1-M13/100) -> 98478.041 | O13: =J13*L13 -> 70816 | P13: =N13-O13 -> 27662.041 | Q13: UPI | R13: Delivered | S13: 44939 | T13: 6 | U13: 4 | V13: Yes | W13: =IF(AND(NOT(R13="Cancelled"),V13="Yes"),1,0) -> 1
A14: ORD00353 | B14: 44931 | C14: CUST0065 | D14: Sneha | E14: Ahmedabad | F14: Gujarat | G14: Jeans | H14: Clothing | I14: Men | J14: 892 | K14: 1458.3971 | L14: 4 | M14: 0 | N14: =K14*L14*(1-M14/100) -> 5833.5884 | O14: =J14*L14 -> 3568 | P14: =N14-O14 -> 2265.5884 | Q14: UPI | R14: Cancelled | T14: 8 | U14: 2 | W14: =IF(AND(NOT(R14="Cancelled"),V14="Yes"),1,0) -> 0
A15: ORD00533 | B15: 44931 | C15: CUST0231 | D15: Nikhil | E15: Delhi | F15: Delhi | G15: Jeans | H15: Clothing | I15: Men | J15: 1265 | K15: 2090.3878 | L15: 3 | M15: 5 | N15: =K15*L15*(1-M15/100) -> 5957.6052 | O15: =J15*L15 -> 3795 | P15: =N15-O15 -> 2162.6052 | Q15: Credit Card | R15: Cancelled | T15: 8 | U15: 3 | W15: =IF(AND(NOT(R15="Cancelled"),V15="Yes"),1,0) -> 0
A16: ORD00022 | B16: 44932 | C16: CUST0256 | D16: Priya | E16: Ahmedabad | F16: Gujarat | G16: Face Cream | H16: Beauty | I16: Skincare | J16: 480 | K16: 531.52966 | L16: 3 | M16: 5 | N16: =K16*L16*(1-M16/100) -> 1514.8595 | O16: =J16*L16 -> 1440 | P16: =N16-O16 -> 74.859526 | Q16: Debit Card | R16: Delivered | S16: 44943 | T16: 6 | U16: 4 | V16: Yes | W16: =IF(AND(NOT(R16="Cancelled"),V16="Yes"),1,0) -> 1
A17: ORD00681 | B17: 44932 | C17: CUST0175 | D17: Arjun | E17: Delhi | F17: Delhi | G17: Shoes | H17: Clothing | I17: Footwear | J17: 1200 | K17: 1293.9325 | L17: 5 | M17: 0 | N17: =K17*L17*(1-M17/100) -> 6469.6627 | O17: =J17*L17 -> 6000 | P17: =N17-O17 -> 469.66268 | Q17: Credit Card | R17: Cancelled | T17: 7 | U17: 3 | W17: =IF(AND(NOT(R17="Cancelled"),V17="Yes"),1,0) -> 0
A18: ORD00020 | B18: 44933 | C18: CUST0232 | D18: Swathi | E18: Chennai | F18: Tamil Nadu | G18: Perfume | H18: Beauty | I18: Fragrance | J18: 649 | K18: 818.41543 | L18: 4 | M18: 20 | N18: =K18*L18*(1-M18/100) -> 2618.9294 | O18: =J18*L18 -> 2596 | P18: =N18-O18 -> 22.929362 | Q18: Debit Card | R18: Delivered | S18: 44942 | T18: 6 | U18: 4 | V18: Yes | W18: =IF(AND(NOT(R18="Cancelled"),V18="Yes"),1,0) -> 1
A19: ORD00094 | B19: 44933 | C19: CUST0101 | D19: Nikhil | E19: Delhi | F19: Delhi | G19: Perfume | H19: Beauty | I19: Fragrance | J19: 545 | K19: 647.07394 | L19: 3 | M19: 10 | N19: =K19*L19*(1-M19/100) -> 1747.0996 | O19: =J19*L19 -> 1635 | P19: =N19-O19 -> 112.09964 | Q19: UPI | R19: Delivered | S19: 44937 | T19: 1 | U19: 5 | V19: No | W19: =IF(AND(NOT(R19="Cancelled"),V19="Yes"),1,0) -> 0
A20: ORD00127 | B20: 44933 | C20: CUST0252 | D20: Swathi | E20: Kolkata | F20: West Bengal | G20: T-Shirt | H20: Clothing | I20: Men | J20: 658 | K20: 1051.9265 | L20: 5 | M20: 15 | N20: =K20*L20*(1-M20/100) -> 4470.6876 | O20: =J20*L20 -> 3290 | P20: =N20-O20 -> 1180.6876 | Q20: UPI | R20: Delivered | S20: 44944 | T20: 6 | U20: 3 | V20: No | W20: =IF(AND(NOT(R20="Cancelled"),V20="Yes"),1,0) -> 0
A21: ORD00915 | B21: 44933 | C21: CUST0204 | D21: Rohit | E21: Mumbai | F21: Maharashtra | G21: T-Shirt | H21: Clothing | I21: Men | J21: 525 | K21: 644.78263 | L21: 1 | M21: 20 | N21: =K21*L21*(1-M21/100) -> 515.82611 | O21: =J21*L21 -> 525 | P21: =N21-O21 -> -9.1738933 | Q21: Credit Card | R21: Cancelled | T21: 9 | U21: 1 | W21: =IF(AND(NOT(R21="Cancelled"),V21="Yes"),1,0) -> 0
A22: ORD00947 | B22: 44933 | C22: CUST0027 | D22: Rahul | E22: Bangalore | F22: Karnataka | G22: Samsung TV | H22: Electronics | I22: TV | J22: 41871 | K22: 52186.75 | L22: 5 | M22: 5 | N22: =K22*L22*(1-M22/100) -> 247887.06 | O22: =J22*L22 -> 209355 | P22: =N22-O22 -> 38532.06 | Q22: Debit Card | R22: Delivered | S22: 44938 | T22: 1 | U22: 5 | V22: No | W22: =IF(AND(NOT(R22="Cancelled"),V22="Yes"),1,0) -> 0
A23: ORD00104 | B23: 44934 | C23: CUST0256 | D23: Rahul | E23: Chennai | F23: Tamil Nadu | G23: Shoes | H23: Clothing | I23: Footwear | J23: 1585 | K23: 1916.8904 | L23: 1 | M23: 5 | N23: =K23*L23*(1-M23/100) -> 1821.0459 | O23: =J23*L23 -> 1585 | P23: =N23-O23 -> 236.04592 | Q23: Debit Card | R23: Delivered | S23: 44945 | T23: 6 | U23: 2 | V23: No | W23: =IF(AND(NOT(R23="Cancelled"),V23="Yes"),1,0) -> 0
A24: ORD00235 | B24: 44934 | C24: CUST0253 | D24: Swathi | E24: Ahmedabad | F24: Gujarat | G24: iPhone 14 | H24: Electronics | I24: Mobile | J24: 74443 | K24: 99616.634 | L24: 2 | M24: 5 | N24: =K24*L24*(1-M24/100) -> 189271.6 | O24: =J24*L24 -> 148886 | P24: =N24-O24 -> 40385.604 | Q24: Credit Card | R24: Delivered | S24: 44947 | T24: 6 | U24: 4 | V24: Yes | W24: =IF(AND(NOT(R24="Cancelled"),V24="Yes"),1,0) -> 1
A25: ORD00623 | B25: 44934 | C25: CUST0164 | D25: Rohit | E25: Hyderabad | F25: Telangana | G25: Mixer | H25: Home | I25: Kitchen | J25: 4882 | K25: 6220.9146 | L25: 1 | M25: 0 | N25: =K25*L25*(1-M25/100) -> 6220.9146 | O25: =J25*L25 -> 4882 | P25: =N25-O25 -> 1338.9146 | Q25: UPI | R25: Delivered | S25: 44941 | T25: 1 | U25: 4 | V25: No | W25: =IF(AND(NOT(R25="Cancelled"),V25="Yes"),1,0) -> 0
A26: ORD00053 | B26: 44935 | C26: CUST0176 | D26: Manoj | E26: Kolkata | F26: West Bengal | G26: Mixer | H26: Home | I26: Kitchen | J26: 3475 | K26: 5066.5993 | L26: 4 | M26: 20 | N26: =K26*L26*(1-M26/100) -> 16213.118 | O26: =J26*L26 -> 13900 | P26: =N26-O26 -> 2313.1178 | Q26: Credit Card | R26: Cancelled | T26: 9 | U26: 1 | W26: =IF(AND(NOT(R26="Cancelled"),V26="Yes"),1,0) -> 0
A27: ORD00422 | B27: 44935 | C27: CUST0117 | D27: Vikram | E27: Bangalore | F27: Karnataka | G27: Face Cream | H27: Beauty | I27: Skincare | J27: 221 | K27: 375.7334 | L27: 5 | M27: 20 | N27: =K27*L27*(1-M27/100) -> 1502.9336 | O27: =J27*L27 -> 1105 | P27: =N27-O27 -> 397.93362 | Q27: Credit Card | R27: Delivered | S27: 44948 | T27: 6 | U27: 4 | V27: Yes | W27: =IF(AND(NOT(R27="Cancelled"),V27="Yes"),1,0) -> 1
A28: ORD00666 | B28: 44935 | C28: CUST0002 | D28: Neha | E28: Ahmedabad | F28: Gujarat | G28: Shoes | H28: Clothing | I28: Footwear | J28: 777 | K28: 1141.1981 | L28: 5 | M28: 0 | N28: =K28*L28*(1-M28/100) -> 5705.9907 | O28: =J28*L28 -> 3885 | P28: =N28-O28 -> 1820.9907 | Q28: UPI | R28: Delivered | S28: 44943 | T28: 1 | U28: 4 | V28: No | W28: =IF(AND(NOT(R28="Cancelled"),V28="Yes"),1,0) -> 0
A29: ORD01023 | B29: 44935 | C29: CUST0242 | D29: Pooja | E29: Mumbai | F29: Maharashtra | G29: Headphones | H29: Electronics | I29: Accessories | J29: 1018 | K29: 1111.6081 | L29: 1 | M29: 0 | N29: =K29*L29*(1-M29/100) -> 1111.6081 | O29: =J29*L29 -> 1018 | P29: =N29-O29 -> 93.608139 | Q29: Credit Card | R29: Cancelled | T29: 10 | U29: 1 | W29: =IF(AND(NOT(R29="Cancelled"),V29="Yes"),1,0) -> 0
A30: ORD00257 | B30: 44937 | C30: CUST0300 | D30: Divya | E30: Chennai | F30: Tamil Nadu | G30: Laptop | H30: Electronics | I30: Computers | J30: 40754 | K30: 68727.394 | L30: 5 | M30: 20 | N30: =K30*L30*(1-M30/100) -> 274909.58 | O30: =J30*L30 -> 203770 | P30: =N30-O30 -> 71139.575 | Q30: COD | R30: Delivered | S30: 44947 | T30: 4 | U30: 2 | V30: No | W30: =IF(AND(NOT(R30="Cancelled"),V30="Yes"),1,0) -> 0
A31: ORD00645 | B31: 44937 | C31: CUST0232 | D31: Divya | E31: Mumbai | F31: Maharashtra | G31: Perfume | H31: Beauty | I31: Fragrance | J31: 630 | K31: 717.22826 | L31: 2 | M31: 5 | N31: =K31*L31*(1-M31/100) -> 1362.7337 | O31: =J31*L31 -> 1260 | P31: =N31-O31 -> 102.73369 | Q31: UPI | R31: Delivered | S31: 44941 | T31: 1 | U31: 4 | V31: No | W31: =IF(AND(NOT(R31="Cancelled"),V31="Yes"),1,0) -> 0
A32: ORD00990 | B32: 44937 | C32: CUST0012 | D32: Arjun | E32: Delhi | F32: Delhi | G32: Jeans | H32: Clothing | I32: Men | J32: 1359 | K32: 1586.636 | L32: 4 | M32: 20 | N32: =K32*L32*(1-M32/100) -> 5077.2353 | O32: =J32*L32 -> 5436 | P32: =N32-O32 -> -358.76466 | Q32: UPI | R32: Delivered | S32: 44944 | T32: 1 | U32: 5 | V32: No | W32: =IF(AND(NOT(R32="Cancelled"),V32="Yes"),1,0) -> 0
A33: ORD01097 | B33: 44937 | C33: CUST0249 | D33: Amit | E33: Delhi | F33: Delhi | G33: Shoes | H33: Clothing | I33: Footwear | J33: 1367 | K33: 1607.0226 | L33: 5 | M33: 5 | N33: =K33*L33*(1-M33/100) -> 7633.3575 | O33: =J33*L33 -> 6835 | P33: =N33-O33 -> 798.35748 | Q33: Debit Card | R33: Cancelled | T33: 9 | U33: 1 | W33: =IF(AND(NOT(R33="Cancelled"),V33="Yes"),1,0) -> 0
A34: ORD00163 | B34: 44938 | C34: CUST0178 | D34: Kavya | E34: Ahmedabad | F34: Gujarat | G34: Jeans | H34: Clothing | I34: Men | J34: 1430 | K34: 1439.4545 | L34: 1 | M34: 15 | N34: =K34*L34*(1-M34/100) -> 1223.5363 | O34: =J34*L34 -> 1430 | P34: =N34-O34 -> -206.4637 | Q34: UPI | R34: Delivered | S34: 44946 | T34: 3 | U34: 2 | V34: No | W34: =IF(AND(NOT(R34="Cancelled"),V34="Yes"),1,0) -> 0
A35: ORD01113 | B35: 44938 | C35: CUST0176 | D35: Ramesh | E35: Chennai | F35: Tamil Nadu | G35: Perfume | H35: Beauty | I35: Fragrance | J35: 619 | K35: 1067.2682 | L35: 2 | M35: 15 | N35: =K35*L35*(1-M35/100) -> 1814.3559 | O35: =J35*L35 -> 1238 | P35: =N35-O35 -> 576.3559 | Q35: UPI | R35: Delivered | S35: 44947 | T35: 4 | U35: 4 | V35: No | W35: =IF(AND(NOT(R35="Cancelled"),V35="Yes"),1,0) -> 0
A36: ORD00011 | B36: 44939 | C36: CUST0294 | D36: Kavya | E36: Ahmedabad | F36: Gujarat | G36: Face Cream | H36: Beauty | I36: Skincare | J36: 578 | K36: 609.40131 | L36: 4 | M36: 10 | N36: =K36*L36*(1-M36/100) -> 2193.8447 | O36: =J36*L36 -> 2312 | P36: =N36-O36 -> -118.15529 | Q36: COD | R36: Delivered | S36: 44948 | T36: 2 | U36: 4 | V36: No | W36: =IF(AND(NOT(R36="Cancelled"),V36="Yes"),1,0) -> 0
A37: ORD00108 | B37: 44939 | C37: CUST0018 | D37: Kavya | E37: Delhi | F37: Delhi | G37: iPhone 14 | H37: Electronics | I37: Mobile | J37: 71289 | K37: 109285.29 | L37: 2 | M37: 15 | N37: =K37*L37*(1-M37/100) -> 185784.99 | O37: =J37*L37 -> 142578 | P37: =N37-O37 -> 43206.986 | Q37: COD | R37: Delivered | S37: 44952 | T37: 6 | U37: 4 | V37: Yes | W37: =IF(AND(NOT(R37="Cancelled"),V37="Yes"),1,0) -> 1
A38: ORD00234 | B38: 44939 | C38: CUST0292 | D38: Divya | E38: Mumbai | F38: Maharashtra | G38: Headphones | H38: Electronics | I38: Accessories | J38: 1220 | K38: 1373.6526 | L38: 3 | M38: 0 | N38: =K38*L38*(1-M38/100) -> 4120.9578 | O38: =J38*L38 -> 3660 | P38: =N38-O38 -> 460.95778 | Q38: COD | R38: Cancelled | T38: 8 | U38: 2 | W38: =IF(AND(NOT(R38="Cancelled"),V38="Yes"),1,0) -> 0
A39: ORD00281 | B39: 44939 | C39: CUST0175 | D39: Manoj | E39: Pune | F39: Maharashtra | G39: Face Cream | H39: Beauty | I39: Skincare | J39: 410 | K39: 434.20316 | L39: 3 | M39: 15 | N39: =K39*L39*(1-M39/100) -> 1107.2181 | O39: =J39*L39 -> 1230 | P39: =N39-O39 -> -122.78194 | Q39: UPI | R39: Cancelled | T39: 9 | U39: 1 | W39: =IF(AND(NOT(R39="Cancelled"),V39="Yes"),1,0) -> 0
A40: ORD00333 | B40: 44939 | C40: CUST0057 | D40: Divya | E40: Pune | F40: Maharashtra | G40: Perfume | H40: Beauty | I40: Fragrance | J40: 584 | K40: 738.19974 | L40: 5 | M40: 10 | N40: =K40*L40*(1-M40/100) -> 3321.8988 | O40: =J40*L40 -> 2920 | P40: =N40-O40 -> 401.89884 | Q40: Debit Card | R40: Delivered | S40: 44948 | T40: 6 | U40: 4 | V40: Yes | W40: =IF(AND(NOT(R40="Cancelled"),V40="Yes"),1,0) -> 1
...

Sheet Pivot_tables and Calculations
A1: Total Revenue | B1: =SUM(#REF!) -> #REF!
A2: Total Orders | B2: =COUNTIF(Ecommerce_Data!R2:R1711,"<>Cancelled") -> 1272
A3: Average Rating | B3: =AVERAGE(Ecommerce_Data!U:U) -> 2.903172
A4: Total Profit | B4: =SUMIF(Ecommerce_Data!R:R,"<>Cancelled",Ecommerce_Data!P:P) -> 10340627
A5: Return Rate | B5: =COUNTIF(Ecommerce_Data!V2:V1711,"Yes")/B2 -> 0.054245283
A6: Profit loss due to return | B6: =SUMIF(Ecommerce_Data!V:V,"Yes",Ecommerce_Data!P:P) -> 935462.63
A7: Profit after return | B7: =B4-B6 -> 9405164.8
E8: Returned | F8: No
E9: Order_status | F9: Delivered
E12: Category | F12: SUM of Revenue | G12: SUM of Profit | H12: AVERAGE of Rating
E13: Electronics | F13: 33344911 | G13: 6937348.1 | H13: 3.3534884
E14: Home | F14: 10183464 | G14: 2171419.8 | H14: 3.2735043
E15: Clothing | F15: 1120039.5 | G15: 235003.49 | H15: 3.5443548
E16: Beauty | F16: 285167.36 | G16: 61393.36 | H16: 3.4594595

Sheet Sheet5
B1: Top 5 Products
A2: Index | B2: Returned | C2: No
A3: 1 | B3: Order_status | C3: Delivered
A4: 2
A5: 3 | B5: Product | C5: SUM of Quantity
A6: 4 | B6: Perfume | C6: 213
A7: 5 | B7: T-Shirt | C7: 202
A8: 6 | B8: Dress | C8: 201
A9: 7 | B9: Shoes | C9: 191
A10: 8 | B10: Sofa | C10: 189
A11: 9 | B11: Laptop | C11: 179
A12: 10 | B12: Samsung TV | C12: 169
A13: 11 | B13: Jeans | C13: 156
A14: 12 | B14: Headphones | C14: 154
B15: Mixer | C15: 151
B16: iPhone 14 | C16: 147
B17: Face Cream | C17: 131

Sheet Monthly
A1: Monthly Orders Trend
A2: Order_status | B2: Delivered
A4: Order count
A5: 760
